<?xml version="1.0" ?>
<!-- =================================================================================== -->
<!-- |    This document was autogenerated by xacro from rover_model_100.xacro          | -->
<!-- |    EDITING THIS FILE BY HAND IS NOT RECOMMENDED                                 | -->
<!-- =================================================================================== -->
<robot name="rover">
  <material name="blue">
    <color rgba="0 0 0.8 1"/>
  </material>
  <material name="black">
    <color rgba="0 0 0 1"/>
  </material>
  <link name="base_weight">
    <inertial>
      <mass value="30"/>
      <inertia ixx="4.9999999999999996e-06" ixy="0.0" ixz="0.0" iyy="4.9999999999999996e-06" iyz="0.0" izz="4.9999999999999996e-06"/>
    </inertial>
    <visual>
      <geometry>
        <box size="0.01 0.01 0.01"/>
      </geometry>
      <material name="black"/>
    </visual>
  </link>
  <link name="base_link">
    <inertial>
      <mass value="10"/>
      <inertia ixx="13.233333333333333" ixy="0" ixz="0" iyy="13.233333333333333" iyz="0" izz="26.45"/>
    </inertial>
    <visual>
      <geometry>
        <cylinder length="0.1" radius="2.3"/>
      </geometry>
      <material name="blue"/>
    </visual>
    <collision>
      <geometry>
        <cylinder length="0.1" radius="2.3"/>
      </geometry>
    </collision>
  </link>
  <joint name="base_link_joint" type="fixed">
    <origin rpy="0 0 0" xyz="1.15 0 -0.55"/>
    <parent link="base_link"/>
    <child link="base_weight"/>
  </joint>
  <link name="left_wheel">
    <visual>
      <origin rpy="1.5707963267948966 0 0" xyz="0 0 0"/>
      <geometry>
        <cylinder length="0.01" radius="1"/>
      </geometry>
    </visual>
    <collision>
      <origin rpy="1.5707963267948966 0 0" xyz="0 0 0"/>
      <geometry>
        <cylinder length="0.01" radius="1"/>
      </geometry>
    </collision>
    <inertial>
      <mass value="15"/>
      <inertia ixx="3.750125" ixy="0" ixz="0" iyy="3.750125" iyz="0" izz="7.5"/>
    </inertial>
  </link>
  <joint name="left_wheel_joint" type="continuous">
    <axis rpy="0 0 0" xyz="0 1 0"/>
    <parent link="base_link"/>
    <child link="left_wheel"/>
    <origin rpy="0 0 0" xyz="0.01 2.5 -base_thickness/2"/>
  </joint>
  <link name="right_wheel">
    <visual>
      <origin rpy="1.5707963267948966 0 0" xyz="0 0 0"/>
      <geometry>
        <cylinder length="0.01" radius="1"/>
      </geometry>
    </visual>
    <collision>
      <origin rpy="1.5707963267948966 0 0" xyz="0 0 0"/>
      <geometry>
        <cylinder length="0.01" radius="1"/>
      </geometry>
    </collision>
    <inertial>
      <mass value="15"/>
      <inertia ixx="3.750125" ixy="0" ixz="0" iyy="3.750125" iyz="0" izz="7.5"/>
    </inertial>
  </link>
  <joint name="right_wheel_joint" type="continuous">
    <axis rpy="0 0 0" xyz="0 1 0"/>
    <parent link="base_link"/>
    <child link="right_wheel"/>
    <origin rpy="0 0 0" xyz="0.01 -2.5 -base_thickness/2"/>
  </joint>
  <link name="caster_wheel">
    <visual>
      <origin rpy="0 0 0" xyz="0 0 0"/>
      <geometry>
        <sphere radius="0.4"/>
      </geometry>
    </visual>
    <collision>
      <origin rpy="0 0 0" xyz="0 0 0"/>
      <geometry>
        <sphere radius="0.4"/>
      </geometry>
    </collision>
    <inertial>
      <mass value="10"/>
      <inertia ixx="0.6400000000000001" ixy="0.0" ixz="0.0" iyy="0.6400000000000001" iyz="0.0" izz="0.6400000000000001"/>
    </inertial>
  </link>
  <joint name="caster_wheel_joint" type="continuous">
    <axis rpy="0 0 0" xyz="0 1 0"/>
    <parent link="base_link"/>
    <child link="caster_wheel"/>
    <origin rpy="0 0 0" xyz="2.07 0 -0.45"/>
  </joint>
</robot>
